[2022-04-11 10:02:05,599] {taskinstance.py:1037} INFO - Dependencies all met for <TaskInstance: hook_dag.transfer_suit_pa manual__2022-04-11T10:02:02.470447+00:00 [queued]>
[2022-04-11 10:02:05,607] {taskinstance.py:1037} INFO - Dependencies all met for <TaskInstance: hook_dag.transfer_suit_pa manual__2022-04-11T10:02:02.470447+00:00 [queued]>
[2022-04-11 10:02:05,607] {taskinstance.py:1243} INFO - 
--------------------------------------------------------------------------------
[2022-04-11 10:02:05,607] {taskinstance.py:1244} INFO - Starting attempt 1 of 2
[2022-04-11 10:02:05,607] {taskinstance.py:1245} INFO - 
--------------------------------------------------------------------------------
[2022-04-11 10:02:05,617] {taskinstance.py:1264} INFO - Executing <Task(Postgres2File): transfer_suit_pa> on 2022-04-11 10:02:02.470447+00:00
[2022-04-11 10:02:05,621] {standard_task_runner.py:52} INFO - Started process 2547 to run task
[2022-04-11 10:02:05,624] {standard_task_runner.py:76} INFO - Running: ['***', 'tasks', 'run', 'hook_dag', 'transfer_suit_pa', 'manual__2022-04-11T10:02:02.470447+00:00', '--job-id', '78', '--raw', '--subdir', 'DAGS_FOLDER/hook_dag.py', '--cfg-path', '/tmp/tmpw8xn13l5', '--error-file', '/tmp/tmpd67i688y']
[2022-04-11 10:02:05,625] {standard_task_runner.py:77} INFO - Job 78: Subtask transfer_suit_pa
[2022-04-11 10:02:05,682] {logging_mixin.py:109} INFO - Running <TaskInstance: hook_dag.transfer_suit_pa manual__2022-04-11T10:02:02.470447+00:00 [running]> on host b69b085ebecc
[2022-04-11 10:02:05,766] {taskinstance.py:1431} INFO - Exporting the following env vars:
AIRFLOW_CTX_DAG_OWNER=***
AIRFLOW_CTX_DAG_ID=hook_dag
AIRFLOW_CTX_TASK_ID=transfer_suit_pa
AIRFLOW_CTX_EXECUTION_DATE=2022-04-11T10:02:02.470447+00:00
AIRFLOW_CTX_DAG_RUN_ID=manual__2022-04-11T10:02:02.470447+00:00
[2022-04-11 10:02:05,794] {base.py:79} INFO - Using connection to: id: postgres_default. Host: postgres, Port: 5432, Schema: ***, Login: ***, Password: ***, extra: {}
[2022-04-11 10:02:05,824] {warnings.py:110} WARNING - /opt/***/plugins/Postgres2File.py:74: FutureWarning: Use of **kwargs is deprecated, use engine_kwargs instead.
  datatoexcel = pd.ExcelWriter(dir_file, header=self.headings, encoding=self.encoding)

[2022-04-11 10:02:05,832] {warnings.py:110} WARNING - /home/***/.local/lib/python3.7/site-packages/***/models/taskinstance.py:1516: FutureWarning: As the xlwt package is no longer maintained, the xlwt engine will be removed in a future version of pandas. This is the only engine in pandas that supports writing in the xls format. Install openpyxl and write to an xlsx file instead. You can set the option io.excel.xls.writer to 'xlwt' to silence this warning. While this option is deprecated and will also raise a warning, it can be globally set and the warning suppressed.
  result = execute_callable(context=context)

[2022-04-11 10:02:05,899] {taskinstance.py:1718} ERROR - Task failed with exception
Traceback (most recent call last):
  File "/opt/airflow/plugins/Postgres2File.py", line 85, in execute
    self._execute(src_hook, context)
  File "/opt/airflow/plugins/Postgres2File.py", line 77, in _execute
    self.convert_excel_to_xml("/opt/airflow/result/pet.xls", "Лист1")
TypeError: convert_excel_to_xml() takes 2 positional arguments but 3 were given

During handling of the above exception, another exception occurred:

Traceback (most recent call last):
  File "/home/airflow/.local/lib/python3.7/site-packages/airflow/models/taskinstance.py", line 1334, in _run_raw_task
    self._execute_task_with_callbacks(context)
  File "/home/airflow/.local/lib/python3.7/site-packages/airflow/models/taskinstance.py", line 1460, in _execute_task_with_callbacks
    result = self._execute_task(context, self.task)
  File "/home/airflow/.local/lib/python3.7/site-packages/airflow/models/taskinstance.py", line 1516, in _execute_task
    result = execute_callable(context=context)
  File "/opt/airflow/plugins/Postgres2File.py", line 89, in execute
    raise exc
NameError: name 'exc' is not defined
[2022-04-11 10:02:05,913] {taskinstance.py:1282} INFO - Marking task as UP_FOR_RETRY. dag_id=hook_dag, task_id=transfer_suit_pa, execution_date=20220411T100202, start_date=20220411T100205, end_date=20220411T100205
[2022-04-11 10:02:05,933] {standard_task_runner.py:92} ERROR - Failed to execute job 78 for task transfer_suit_pa
Traceback (most recent call last):
  File "/opt/airflow/plugins/Postgres2File.py", line 85, in execute
    self._execute(src_hook, context)
  File "/opt/airflow/plugins/Postgres2File.py", line 77, in _execute
    self.convert_excel_to_xml("/opt/airflow/result/pet.xls", "Лист1")
TypeError: convert_excel_to_xml() takes 2 positional arguments but 3 were given

During handling of the above exception, another exception occurred:

Traceback (most recent call last):
  File "/home/airflow/.local/lib/python3.7/site-packages/airflow/task/task_runner/standard_task_runner.py", line 85, in _start_by_fork
    args.func(args, dag=self.dag)
  File "/home/airflow/.local/lib/python3.7/site-packages/airflow/cli/cli_parser.py", line 48, in command
    return func(*args, **kwargs)
  File "/home/airflow/.local/lib/python3.7/site-packages/airflow/utils/cli.py", line 92, in wrapper
    return f(*args, **kwargs)
  File "/home/airflow/.local/lib/python3.7/site-packages/airflow/cli/commands/task_command.py", line 298, in task_run
    _run_task_by_selected_method(args, dag, ti)
  File "/home/airflow/.local/lib/python3.7/site-packages/airflow/cli/commands/task_command.py", line 107, in _run_task_by_selected_method
    _run_raw_task(args, ti)
  File "/home/airflow/.local/lib/python3.7/site-packages/airflow/cli/commands/task_command.py", line 184, in _run_raw_task
    error_file=args.error_file,
  File "/home/airflow/.local/lib/python3.7/site-packages/airflow/utils/session.py", line 70, in wrapper
    return func(*args, session=session, **kwargs)
  File "/home/airflow/.local/lib/python3.7/site-packages/airflow/models/taskinstance.py", line 1334, in _run_raw_task
    self._execute_task_with_callbacks(context)
  File "/home/airflow/.local/lib/python3.7/site-packages/airflow/models/taskinstance.py", line 1460, in _execute_task_with_callbacks
    result = self._execute_task(context, self.task)
  File "/home/airflow/.local/lib/python3.7/site-packages/airflow/models/taskinstance.py", line 1516, in _execute_task
    result = execute_callable(context=context)
  File "/opt/airflow/plugins/Postgres2File.py", line 89, in execute
    raise exc
NameError: name 'exc' is not defined
[2022-04-11 10:02:05,959] {local_task_job.py:154} INFO - Task exited with return code 1
[2022-04-11 10:02:05,992] {local_task_job.py:264} INFO - 0 downstream tasks scheduled from follow-on schedule check
