[2022-04-19 11:47:37,521] {taskinstance.py:1037} INFO - Dependencies all met for <TaskInstance: hook_dag.log_sensor manual__2022-04-19T11:47:36.014903+00:00 [queued]>
[2022-04-19 11:47:37,529] {taskinstance.py:1037} INFO - Dependencies all met for <TaskInstance: hook_dag.log_sensor manual__2022-04-19T11:47:36.014903+00:00 [queued]>
[2022-04-19 11:47:37,529] {taskinstance.py:1243} INFO - 
--------------------------------------------------------------------------------
[2022-04-19 11:47:37,529] {taskinstance.py:1244} INFO - Starting attempt 1 of 2
[2022-04-19 11:47:37,529] {taskinstance.py:1245} INFO - 
--------------------------------------------------------------------------------
[2022-04-19 11:47:37,537] {taskinstance.py:1264} INFO - Executing <Task(SqlSensor): log_sensor> on 2022-04-19 11:47:36.014903+00:00
[2022-04-19 11:47:37,540] {standard_task_runner.py:52} INFO - Started process 8933 to run task
[2022-04-19 11:47:37,543] {standard_task_runner.py:76} INFO - Running: ['***', 'tasks', 'run', 'hook_dag', 'log_sensor', 'manual__2022-04-19T11:47:36.014903+00:00', '--job-id', '325', '--raw', '--subdir', 'DAGS_FOLDER/hook_dag.py', '--cfg-path', '/tmp/tmpq9vskk3f', '--error-file', '/tmp/tmp9pgpi0ag']
[2022-04-19 11:47:37,544] {standard_task_runner.py:77} INFO - Job 325: Subtask log_sensor
[2022-04-19 11:47:37,584] {logging_mixin.py:109} INFO - Running <TaskInstance: hook_dag.log_sensor manual__2022-04-19T11:47:36.014903+00:00 [running]> on host 22e04adb6bfa
[2022-04-19 11:47:37,627] {taskinstance.py:1431} INFO - Exporting the following env vars:
AIRFLOW_CTX_DAG_OWNER=***
AIRFLOW_CTX_DAG_ID=hook_dag
AIRFLOW_CTX_TASK_ID=log_sensor
AIRFLOW_CTX_EXECUTION_DATE=2022-04-19T11:47:36.014903+00:00
AIRFLOW_CTX_DAG_RUN_ID=manual__2022-04-19T11:47:36.014903+00:00
[2022-04-19 11:47:37,633] {base.py:79} INFO - Using connection to: id: postgres_default. Host: postgres, Port: 5432, Schema: ***, Login: ***, Password: ***, extra: {}
[2022-04-19 11:47:37,682] {sql.py:98} INFO - Poking: select case when q = 'true' then 1 else 0 end as q from  (
	select case when count(id)=0 then 'true' else 'false' end as q
	from list_flow_log
	where object_flow = 1 and status = 1
) t1; (with parameters None)
[2022-04-19 11:47:37,687] {base.py:79} INFO - Using connection to: id: postgres_default. Host: postgres, Port: 5432, Schema: ***, Login: ***, Password: ***, extra: {}
[2022-04-19 11:48:23,098] {local_task_job.py:212} WARNING - State of this instance has been externally set to restarting. Terminating instance.
[2022-04-19 11:48:23,100] {process_utils.py:124} INFO - Sending Signals.SIGTERM to group 8933. PIDs of all processes in the group: [8933]
[2022-04-19 11:48:23,100] {process_utils.py:75} INFO - Sending the signal Signals.SIGTERM to group 8933
[2022-04-19 11:48:23,100] {taskinstance.py:1413} ERROR - Received SIGTERM. Terminating subprocesses.
[2022-04-19 11:48:23,108] {taskinstance.py:1718} ERROR - Task failed with exception
Traceback (most recent call last):
  File "/home/airflow/.local/lib/python3.7/site-packages/airflow/models/taskinstance.py", line 1334, in _run_raw_task
    self._execute_task_with_callbacks(context)
  File "/home/airflow/.local/lib/python3.7/site-packages/airflow/models/taskinstance.py", line 1460, in _execute_task_with_callbacks
    result = self._execute_task(context, self.task)
  File "/home/airflow/.local/lib/python3.7/site-packages/airflow/models/taskinstance.py", line 1516, in _execute_task
    result = execute_callable(context=context)
  File "/home/airflow/.local/lib/python3.7/site-packages/airflow/sensors/base.py", line 249, in execute
    time.sleep(self._get_next_poke_interval(started_at, run_duration, try_number))
  File "/home/airflow/.local/lib/python3.7/site-packages/airflow/models/taskinstance.py", line 1415, in signal_handler
    raise AirflowException("Task received SIGTERM signal")
airflow.exceptions.AirflowException: Task received SIGTERM signal
[2022-04-19 11:48:23,133] {taskinstance.py:1282} INFO - Marking task as UP_FOR_RETRY. dag_id=hook_dag, task_id=log_sensor, execution_date=20220419T114736, start_date=20220419T114737, end_date=20220419T114823
[2022-04-19 11:48:23,143] {standard_task_runner.py:92} ERROR - Failed to execute job 325 for task log_sensor
Traceback (most recent call last):
  File "/home/airflow/.local/lib/python3.7/site-packages/airflow/task/task_runner/standard_task_runner.py", line 85, in _start_by_fork
    args.func(args, dag=self.dag)
  File "/home/airflow/.local/lib/python3.7/site-packages/airflow/cli/cli_parser.py", line 48, in command
    return func(*args, **kwargs)
  File "/home/airflow/.local/lib/python3.7/site-packages/airflow/utils/cli.py", line 92, in wrapper
    return f(*args, **kwargs)
  File "/home/airflow/.local/lib/python3.7/site-packages/airflow/cli/commands/task_command.py", line 298, in task_run
    _run_task_by_selected_method(args, dag, ti)
  File "/home/airflow/.local/lib/python3.7/site-packages/airflow/cli/commands/task_command.py", line 107, in _run_task_by_selected_method
    _run_raw_task(args, ti)
  File "/home/airflow/.local/lib/python3.7/site-packages/airflow/cli/commands/task_command.py", line 184, in _run_raw_task
    error_file=args.error_file,
  File "/home/airflow/.local/lib/python3.7/site-packages/airflow/utils/session.py", line 70, in wrapper
    return func(*args, session=session, **kwargs)
  File "/home/airflow/.local/lib/python3.7/site-packages/airflow/models/taskinstance.py", line 1334, in _run_raw_task
    self._execute_task_with_callbacks(context)
  File "/home/airflow/.local/lib/python3.7/site-packages/airflow/models/taskinstance.py", line 1460, in _execute_task_with_callbacks
    result = self._execute_task(context, self.task)
  File "/home/airflow/.local/lib/python3.7/site-packages/airflow/models/taskinstance.py", line 1516, in _execute_task
    result = execute_callable(context=context)
  File "/home/airflow/.local/lib/python3.7/site-packages/airflow/sensors/base.py", line 249, in execute
    time.sleep(self._get_next_poke_interval(started_at, run_duration, try_number))
  File "/home/airflow/.local/lib/python3.7/site-packages/airflow/models/taskinstance.py", line 1415, in signal_handler
    raise AirflowException("Task received SIGTERM signal")
airflow.exceptions.AirflowException: Task received SIGTERM signal
[2022-04-19 11:48:23,152] {process_utils.py:70} INFO - Process psutil.Process(pid=8933, status='terminated', exitcode=1, started='11:47:37') (8933) terminated with exit code 1
