[2022-04-25 08:38:25,698] {taskinstance.py:1037} INFO - Dependencies all met for <TaskInstance: cso_2295_ipo_2_cso_xls.py.transfer_cso_calendar manual__2022-04-25T08:36:56.447912+00:00 [queued]>
[2022-04-25 08:38:25,707] {taskinstance.py:1037} INFO - Dependencies all met for <TaskInstance: cso_2295_ipo_2_cso_xls.py.transfer_cso_calendar manual__2022-04-25T08:36:56.447912+00:00 [queued]>
[2022-04-25 08:38:25,708] {taskinstance.py:1243} INFO - 
--------------------------------------------------------------------------------
[2022-04-25 08:38:25,708] {taskinstance.py:1244} INFO - Starting attempt 1 of 1
[2022-04-25 08:38:25,708] {taskinstance.py:1245} INFO - 
--------------------------------------------------------------------------------
[2022-04-25 08:38:25,716] {taskinstance.py:1264} INFO - Executing <Task(Postgres2File): transfer_cso_calendar> on 2022-04-25 08:36:56.447912+00:00
[2022-04-25 08:38:25,720] {standard_task_runner.py:52} INFO - Started process 1926 to run task
[2022-04-25 08:38:25,723] {standard_task_runner.py:76} INFO - Running: ['***', 'tasks', 'run', 'cso_2295_ipo_2_cso_xls.py', 'transfer_cso_calendar', 'manual__2022-04-25T08:36:56.447912+00:00', '--job-id', '1122', '--raw', '--subdir', 'DAGS_FOLDER/cso_2295/cso_2295_ipo_2_cso_xls.py', '--cfg-path', '/tmp/tmpmttwtabi', '--error-file', '/tmp/tmp31qopt7t']
[2022-04-25 08:38:25,723] {standard_task_runner.py:77} INFO - Job 1122: Subtask transfer_cso_calendar
[2022-04-25 08:38:25,766] {logging_mixin.py:109} INFO - Running <TaskInstance: cso_2295_ipo_2_cso_xls.py.transfer_cso_calendar manual__2022-04-25T08:36:56.447912+00:00 [running]> on host 22e04adb6bfa
[2022-04-25 08:38:25,805] {taskinstance.py:1431} INFO - Exporting the following env vars:
AIRFLOW_CTX_DAG_OWNER=***
AIRFLOW_CTX_DAG_ID=cso_2295_ipo_2_cso_xls.py
AIRFLOW_CTX_TASK_ID=transfer_cso_calendar
AIRFLOW_CTX_EXECUTION_DATE=2022-04-25T08:36:56.447912+00:00
AIRFLOW_CTX_DAG_RUN_ID=manual__2022-04-25T08:36:56.447912+00:00
[2022-04-25 08:38:25,811] {base.py:79} INFO - Using connection to: id: postgres_default. Host: postgres, Port: 5432, Schema: ***, Login: ***, Password: ***, extra: {}
[2022-04-25 08:38:25,861] {taskinstance.py:1718} ERROR - Task failed with exception
Traceback (most recent call last):
  File "/opt/airflow/plugins/Postgres2File.py", line 133, in execute
    self._execute(src_hook, context)
  File "/opt/airflow/plugins/Postgres2File.py", line 68, in _execute
    for colno, heading in enumerate(headings, start=0):
NameError: name 'headings' is not defined

During handling of the above exception, another exception occurred:

Traceback (most recent call last):
  File "/home/airflow/.local/lib/python3.7/site-packages/airflow/models/taskinstance.py", line 1334, in _run_raw_task
    self._execute_task_with_callbacks(context)
  File "/home/airflow/.local/lib/python3.7/site-packages/airflow/models/taskinstance.py", line 1460, in _execute_task_with_callbacks
    result = self._execute_task(context, self.task)
  File "/home/airflow/.local/lib/python3.7/site-packages/airflow/models/taskinstance.py", line 1516, in _execute_task
    result = execute_callable(context=context)
  File "/opt/airflow/plugins/Postgres2File.py", line 137, in execute
    raise exc
NameError: name 'exc' is not defined
[2022-04-25 08:38:25,897] {taskinstance.py:1282} INFO - Marking task as FAILED. dag_id=cso_2295_ipo_2_cso_xls.py, task_id=transfer_cso_calendar, execution_date=20220425T083656, start_date=20220425T083825, end_date=20220425T083825
[2022-04-25 08:38:26,091] {standard_task_runner.py:92} ERROR - Failed to execute job 1122 for task transfer_cso_calendar
Traceback (most recent call last):
  File "/opt/airflow/plugins/Postgres2File.py", line 133, in execute
    self._execute(src_hook, context)
  File "/opt/airflow/plugins/Postgres2File.py", line 68, in _execute
    for colno, heading in enumerate(headings, start=0):
NameError: name 'headings' is not defined

During handling of the above exception, another exception occurred:

Traceback (most recent call last):
  File "/home/airflow/.local/lib/python3.7/site-packages/airflow/task/task_runner/standard_task_runner.py", line 85, in _start_by_fork
    args.func(args, dag=self.dag)
  File "/home/airflow/.local/lib/python3.7/site-packages/airflow/cli/cli_parser.py", line 48, in command
    return func(*args, **kwargs)
  File "/home/airflow/.local/lib/python3.7/site-packages/airflow/utils/cli.py", line 92, in wrapper
    return f(*args, **kwargs)
  File "/home/airflow/.local/lib/python3.7/site-packages/airflow/cli/commands/task_command.py", line 298, in task_run
    _run_task_by_selected_method(args, dag, ti)
  File "/home/airflow/.local/lib/python3.7/site-packages/airflow/cli/commands/task_command.py", line 107, in _run_task_by_selected_method
    _run_raw_task(args, ti)
  File "/home/airflow/.local/lib/python3.7/site-packages/airflow/cli/commands/task_command.py", line 184, in _run_raw_task
    error_file=args.error_file,
  File "/home/airflow/.local/lib/python3.7/site-packages/airflow/utils/session.py", line 70, in wrapper
    return func(*args, session=session, **kwargs)
  File "/home/airflow/.local/lib/python3.7/site-packages/airflow/models/taskinstance.py", line 1334, in _run_raw_task
    self._execute_task_with_callbacks(context)
  File "/home/airflow/.local/lib/python3.7/site-packages/airflow/models/taskinstance.py", line 1460, in _execute_task_with_callbacks
    result = self._execute_task(context, self.task)
  File "/home/airflow/.local/lib/python3.7/site-packages/airflow/models/taskinstance.py", line 1516, in _execute_task
    result = execute_callable(context=context)
  File "/opt/airflow/plugins/Postgres2File.py", line 137, in execute
    raise exc
NameError: name 'exc' is not defined
[2022-04-25 08:38:26,216] {local_task_job.py:154} INFO - Task exited with return code 1
[2022-04-25 08:38:26,255] {base.py:79} INFO - Using connection to: id: postgres_default. Host: postgres, Port: 5432, Schema: ***, Login: ***, Password: ***, extra: {}
[2022-04-25 08:38:26,259] {dbapi.py:225} INFO - Running statement: update list_flow_log
                set t_end=NOW(), status=3, code_error=3, comment = '*Task*: transfer_cso_calendar'
                where id = 100;, parameters: None
[2022-04-25 08:38:26,260] {dbapi.py:233} INFO - Rows affected: 1
[2022-04-25 08:38:26,280] {local_task_job.py:264} INFO - 0 downstream tasks scheduled from follow-on schedule check
