[2022-04-19 10:26:27,004] {taskinstance.py:1037} INFO - Dependencies all met for <TaskInstance: hook_dag.branching manual__2022-04-19T10:25:17.448479+00:00 [queued]>
[2022-04-19 10:26:27,016] {taskinstance.py:1037} INFO - Dependencies all met for <TaskInstance: hook_dag.branching manual__2022-04-19T10:25:17.448479+00:00 [queued]>
[2022-04-19 10:26:27,016] {taskinstance.py:1243} INFO - 
--------------------------------------------------------------------------------
[2022-04-19 10:26:27,016] {taskinstance.py:1244} INFO - Starting attempt 1 of 2
[2022-04-19 10:26:27,016] {taskinstance.py:1245} INFO - 
--------------------------------------------------------------------------------
[2022-04-19 10:26:27,024] {taskinstance.py:1264} INFO - Executing <Task(BranchPythonOperator): branching> on 2022-04-19 10:25:17.448479+00:00
[2022-04-19 10:26:27,027] {standard_task_runner.py:52} INFO - Started process 4830 to run task
[2022-04-19 10:26:27,030] {standard_task_runner.py:76} INFO - Running: ['***', 'tasks', 'run', 'hook_dag', 'branching', 'manual__2022-04-19T10:25:17.448479+00:00', '--job-id', '262', '--raw', '--subdir', 'DAGS_FOLDER/hook_dag.py', '--cfg-path', '/tmp/tmpukd948lf', '--error-file', '/tmp/tmp0cj9o4rg']
[2022-04-19 10:26:27,030] {standard_task_runner.py:77} INFO - Job 262: Subtask branching
[2022-04-19 10:26:27,071] {logging_mixin.py:109} INFO - Running <TaskInstance: hook_dag.branching manual__2022-04-19T10:25:17.448479+00:00 [running]> on host 22e04adb6bfa
[2022-04-19 10:26:27,115] {taskinstance.py:1431} INFO - Exporting the following env vars:
AIRFLOW_CTX_DAG_OWNER=***
AIRFLOW_CTX_DAG_ID=hook_dag
AIRFLOW_CTX_TASK_ID=branching
AIRFLOW_CTX_EXECUTION_DATE=2022-04-19T10:25:17.448479+00:00
AIRFLOW_CTX_DAG_RUN_ID=manual__2022-04-19T10:25:17.448479+00:00
[2022-04-19 10:26:27,120] {taskinstance.py:1718} ERROR - Task failed with exception
Traceback (most recent call last):
  File "/home/airflow/.local/lib/python3.7/site-packages/airflow/models/taskinstance.py", line 1334, in _run_raw_task
    self._execute_task_with_callbacks(context)
  File "/home/airflow/.local/lib/python3.7/site-packages/airflow/models/taskinstance.py", line 1460, in _execute_task_with_callbacks
    result = self._execute_task(context, self.task)
  File "/home/airflow/.local/lib/python3.7/site-packages/airflow/models/taskinstance.py", line 1516, in _execute_task
    result = execute_callable(context=context)
  File "/home/airflow/.local/lib/python3.7/site-packages/airflow/operators/python.py", line 206, in execute
    branch = super().execute(context)
  File "/home/airflow/.local/lib/python3.7/site-packages/airflow/operators/python.py", line 174, in execute
    return_value = self.execute_callable()
  File "/home/airflow/.local/lib/python3.7/site-packages/airflow/operators/python.py", line 188, in execute_callable
    return self.python_callable(*self.op_args, **self.op_kwargs)
  File "/opt/airflow/dags/hook_dag.py", line 94, in f_branching
    qrows = len(id_s)
TypeError: object of type 'NoneType' has no len()
[2022-04-19 10:26:27,129] {taskinstance.py:1282} INFO - Marking task as UP_FOR_RETRY. dag_id=hook_dag, task_id=branching, execution_date=20220419T102517, start_date=20220419T102627, end_date=20220419T102627
[2022-04-19 10:26:27,137] {standard_task_runner.py:92} ERROR - Failed to execute job 262 for task branching
Traceback (most recent call last):
  File "/home/airflow/.local/lib/python3.7/site-packages/airflow/task/task_runner/standard_task_runner.py", line 85, in _start_by_fork
    args.func(args, dag=self.dag)
  File "/home/airflow/.local/lib/python3.7/site-packages/airflow/cli/cli_parser.py", line 48, in command
    return func(*args, **kwargs)
  File "/home/airflow/.local/lib/python3.7/site-packages/airflow/utils/cli.py", line 92, in wrapper
    return f(*args, **kwargs)
  File "/home/airflow/.local/lib/python3.7/site-packages/airflow/cli/commands/task_command.py", line 298, in task_run
    _run_task_by_selected_method(args, dag, ti)
  File "/home/airflow/.local/lib/python3.7/site-packages/airflow/cli/commands/task_command.py", line 107, in _run_task_by_selected_method
    _run_raw_task(args, ti)
  File "/home/airflow/.local/lib/python3.7/site-packages/airflow/cli/commands/task_command.py", line 184, in _run_raw_task
    error_file=args.error_file,
  File "/home/airflow/.local/lib/python3.7/site-packages/airflow/utils/session.py", line 70, in wrapper
    return func(*args, session=session, **kwargs)
  File "/home/airflow/.local/lib/python3.7/site-packages/airflow/models/taskinstance.py", line 1334, in _run_raw_task
    self._execute_task_with_callbacks(context)
  File "/home/airflow/.local/lib/python3.7/site-packages/airflow/models/taskinstance.py", line 1460, in _execute_task_with_callbacks
    result = self._execute_task(context, self.task)
  File "/home/airflow/.local/lib/python3.7/site-packages/airflow/models/taskinstance.py", line 1516, in _execute_task
    result = execute_callable(context=context)
  File "/home/airflow/.local/lib/python3.7/site-packages/airflow/operators/python.py", line 206, in execute
    branch = super().execute(context)
  File "/home/airflow/.local/lib/python3.7/site-packages/airflow/operators/python.py", line 174, in execute
    return_value = self.execute_callable()
  File "/home/airflow/.local/lib/python3.7/site-packages/airflow/operators/python.py", line 188, in execute_callable
    return self.python_callable(*self.op_args, **self.op_kwargs)
  File "/opt/airflow/dags/hook_dag.py", line 94, in f_branching
    qrows = len(id_s)
TypeError: object of type 'NoneType' has no len()
[2022-04-19 10:26:27,164] {local_task_job.py:154} INFO - Task exited with return code 1
[2022-04-19 10:26:27,191] {local_task_job.py:264} INFO - 0 downstream tasks scheduled from follow-on schedule check
