[2022-04-21 21:03:59,982] {taskinstance.py:1037} INFO - Dependencies all met for <TaskInstance: cso_2295_ipo_2_cso.py.check_system_target1 manual__2022-04-21T21:03:49.018331+00:00 [queued]>
[2022-04-21 21:03:59,994] {taskinstance.py:1037} INFO - Dependencies all met for <TaskInstance: cso_2295_ipo_2_cso.py.check_system_target1 manual__2022-04-21T21:03:49.018331+00:00 [queued]>
[2022-04-21 21:03:59,994] {taskinstance.py:1243} INFO - 
--------------------------------------------------------------------------------
[2022-04-21 21:03:59,994] {taskinstance.py:1244} INFO - Starting attempt 1 of 1
[2022-04-21 21:03:59,994] {taskinstance.py:1245} INFO - 
--------------------------------------------------------------------------------
[2022-04-21 21:04:00,009] {taskinstance.py:1264} INFO - Executing <Task(BranchPythonOperator): check_system_target1> on 2022-04-21 21:03:49.018331+00:00
[2022-04-21 21:04:00,014] {standard_task_runner.py:52} INFO - Started process 33974 to run task
[2022-04-21 21:04:00,016] {standard_task_runner.py:76} INFO - Running: ['***', 'tasks', 'run', 'cso_2295_ipo_2_cso.py', 'check_system_target1', 'manual__2022-04-21T21:03:49.018331+00:00', '--job-id', '826', '--raw', '--subdir', 'DAGS_FOLDER/cso_2295/cso_2295_ipo_2_cso.py', '--cfg-path', '/tmp/tmp70ukdmgh', '--error-file', '/tmp/tmp_jw7ont3']
[2022-04-21 21:04:00,017] {standard_task_runner.py:77} INFO - Job 826: Subtask check_system_target1
[2022-04-21 21:04:00,065] {logging_mixin.py:109} INFO - Running <TaskInstance: cso_2295_ipo_2_cso.py.check_system_target1 manual__2022-04-21T21:03:49.018331+00:00 [running]> on host 22e04adb6bfa
[2022-04-21 21:04:00,117] {taskinstance.py:1431} INFO - Exporting the following env vars:
AIRFLOW_CTX_DAG_OWNER=***
AIRFLOW_CTX_DAG_ID=cso_2295_ipo_2_cso.py
AIRFLOW_CTX_TASK_ID=check_system_target1
AIRFLOW_CTX_EXECUTION_DATE=2022-04-21T21:03:49.018331+00:00
AIRFLOW_CTX_DAG_RUN_ID=manual__2022-04-21T21:03:49.018331+00:00
[2022-04-21 21:04:00,117] {python.py:175} INFO - Done. Returned value was: transfer_org
[2022-04-21 21:04:00,129] {taskinstance.py:1718} ERROR - Task failed with exception
Traceback (most recent call last):
  File "/home/airflow/.local/lib/python3.7/site-packages/airflow/models/taskinstance.py", line 1334, in _run_raw_task
    self._execute_task_with_callbacks(context)
  File "/home/airflow/.local/lib/python3.7/site-packages/airflow/models/taskinstance.py", line 1460, in _execute_task_with_callbacks
    result = self._execute_task(context, self.task)
  File "/home/airflow/.local/lib/python3.7/site-packages/airflow/models/taskinstance.py", line 1516, in _execute_task
    result = execute_callable(context=context)
  File "/home/airflow/.local/lib/python3.7/site-packages/airflow/operators/python.py", line 218, in execute
    f"Branch callable must return valid task_ids. Invalid tasks found: {invalid_task_ids}"
airflow.exceptions.AirflowException: Branch callable must return valid task_ids. Invalid tasks found: {'transfer_org'}
[2022-04-21 21:04:00,138] {taskinstance.py:1282} INFO - Marking task as FAILED. dag_id=cso_2295_ipo_2_cso.py, task_id=check_system_target1, execution_date=20220421T210349, start_date=20220421T210359, end_date=20220421T210400
[2022-04-21 21:04:00,146] {standard_task_runner.py:92} ERROR - Failed to execute job 826 for task check_system_target1
Traceback (most recent call last):
  File "/home/airflow/.local/lib/python3.7/site-packages/airflow/task/task_runner/standard_task_runner.py", line 85, in _start_by_fork
    args.func(args, dag=self.dag)
  File "/home/airflow/.local/lib/python3.7/site-packages/airflow/cli/cli_parser.py", line 48, in command
    return func(*args, **kwargs)
  File "/home/airflow/.local/lib/python3.7/site-packages/airflow/utils/cli.py", line 92, in wrapper
    return f(*args, **kwargs)
  File "/home/airflow/.local/lib/python3.7/site-packages/airflow/cli/commands/task_command.py", line 298, in task_run
    _run_task_by_selected_method(args, dag, ti)
  File "/home/airflow/.local/lib/python3.7/site-packages/airflow/cli/commands/task_command.py", line 107, in _run_task_by_selected_method
    _run_raw_task(args, ti)
  File "/home/airflow/.local/lib/python3.7/site-packages/airflow/cli/commands/task_command.py", line 184, in _run_raw_task
    error_file=args.error_file,
  File "/home/airflow/.local/lib/python3.7/site-packages/airflow/utils/session.py", line 70, in wrapper
    return func(*args, session=session, **kwargs)
  File "/home/airflow/.local/lib/python3.7/site-packages/airflow/models/taskinstance.py", line 1334, in _run_raw_task
    self._execute_task_with_callbacks(context)
  File "/home/airflow/.local/lib/python3.7/site-packages/airflow/models/taskinstance.py", line 1460, in _execute_task_with_callbacks
    result = self._execute_task(context, self.task)
  File "/home/airflow/.local/lib/python3.7/site-packages/airflow/models/taskinstance.py", line 1516, in _execute_task
    result = execute_callable(context=context)
  File "/home/airflow/.local/lib/python3.7/site-packages/airflow/operators/python.py", line 218, in execute
    f"Branch callable must return valid task_ids. Invalid tasks found: {invalid_task_ids}"
airflow.exceptions.AirflowException: Branch callable must return valid task_ids. Invalid tasks found: {'transfer_org'}
[2022-04-21 21:04:00,190] {local_task_job.py:154} INFO - Task exited with return code 1
[2022-04-21 21:04:00,215] {base.py:79} INFO - Using connection to: id: postgres_default. Host: postgres, Port: 5432, Schema: ***, Login: ***, Password: ***, extra: {}
[2022-04-21 21:04:00,220] {dbapi.py:225} INFO - Running statement: update list_flow_log
                set t_end=NOW(), status=3, code_error=3, comment = '*Task*: check_system_target1'
                where id = 66;, parameters: None
[2022-04-21 21:04:00,221] {dbapi.py:233} INFO - Rows affected: 1
[2022-04-21 21:04:00,247] {local_task_job.py:264} INFO - 0 downstream tasks scheduled from follow-on schedule check
