[2022-04-21 21:22:32,152] {taskinstance.py:1037} INFO - Dependencies all met for <TaskInstance: cso_2295_ipo_2_cso.py.transfer_cso_pers manual__2022-04-21T21:21:16.706497+00:00 [queued]>
[2022-04-21 21:22:32,164] {taskinstance.py:1037} INFO - Dependencies all met for <TaskInstance: cso_2295_ipo_2_cso.py.transfer_cso_pers manual__2022-04-21T21:21:16.706497+00:00 [queued]>
[2022-04-21 21:22:32,164] {taskinstance.py:1243} INFO - 
--------------------------------------------------------------------------------
[2022-04-21 21:22:32,164] {taskinstance.py:1244} INFO - Starting attempt 1 of 1
[2022-04-21 21:22:32,164] {taskinstance.py:1245} INFO - 
--------------------------------------------------------------------------------
[2022-04-21 21:22:32,173] {taskinstance.py:1264} INFO - Executing <Task(Postgres2File): transfer_cso_pers> on 2022-04-21 21:21:16.706497+00:00
[2022-04-21 21:22:32,178] {standard_task_runner.py:52} INFO - Started process 35119 to run task
[2022-04-21 21:22:32,180] {standard_task_runner.py:76} INFO - Running: ['***', 'tasks', 'run', 'cso_2295_ipo_2_cso.py', 'transfer_cso_pers', 'manual__2022-04-21T21:21:16.706497+00:00', '--job-id', '912', '--raw', '--subdir', 'DAGS_FOLDER/cso_2295/cso_2295_ipo_2_cso.py', '--cfg-path', '/tmp/tmpllp9mm8p', '--error-file', '/tmp/tmpfy14ndwt']
[2022-04-21 21:22:32,181] {standard_task_runner.py:77} INFO - Job 912: Subtask transfer_cso_pers
[2022-04-21 21:22:32,224] {logging_mixin.py:109} INFO - Running <TaskInstance: cso_2295_ipo_2_cso.py.transfer_cso_pers manual__2022-04-21T21:21:16.706497+00:00 [running]> on host 22e04adb6bfa
[2022-04-21 21:22:32,278] {taskinstance.py:1431} INFO - Exporting the following env vars:
AIRFLOW_CTX_DAG_OWNER=***
AIRFLOW_CTX_DAG_ID=cso_2295_ipo_2_cso.py
AIRFLOW_CTX_TASK_ID=transfer_cso_pers
AIRFLOW_CTX_EXECUTION_DATE=2022-04-21T21:21:16.706497+00:00
AIRFLOW_CTX_DAG_RUN_ID=manual__2022-04-21T21:21:16.706497+00:00
[2022-04-21 21:22:32,285] {base.py:79} INFO - Using connection to: id: postgres_default. Host: postgres, Port: 5432, Schema: ***, Login: ***, Password: ***, extra: {}
[2022-04-21 21:22:32,296] {taskinstance.py:1718} ERROR - Task failed with exception
Traceback (most recent call last):
  File "/opt/airflow/plugins/Postgres2File.py", line 111, in execute
    self._execute(src_hook, context)
  File "/opt/airflow/plugins/Postgres2File.py", line 71, in _execute
    cursor.execute(self.sql)
psycopg2.errors.UndefinedColumn: column "nachn" does not exist
LINE 1: select PERNR, NACHN, VORNA, MIDNM, ORGEH, PLANS, PLTXT, CHPE...
                      ^


During handling of the above exception, another exception occurred:

Traceback (most recent call last):
  File "/home/airflow/.local/lib/python3.7/site-packages/airflow/models/taskinstance.py", line 1334, in _run_raw_task
    self._execute_task_with_callbacks(context)
  File "/home/airflow/.local/lib/python3.7/site-packages/airflow/models/taskinstance.py", line 1460, in _execute_task_with_callbacks
    result = self._execute_task(context, self.task)
  File "/home/airflow/.local/lib/python3.7/site-packages/airflow/models/taskinstance.py", line 1516, in _execute_task
    result = execute_callable(context=context)
  File "/opt/airflow/plugins/Postgres2File.py", line 115, in execute
    raise exc
NameError: name 'exc' is not defined
[2022-04-21 21:22:32,306] {taskinstance.py:1282} INFO - Marking task as FAILED. dag_id=cso_2295_ipo_2_cso.py, task_id=transfer_cso_pers, execution_date=20220421T212116, start_date=20220421T212232, end_date=20220421T212232
[2022-04-21 21:22:32,316] {standard_task_runner.py:92} ERROR - Failed to execute job 912 for task transfer_cso_pers
Traceback (most recent call last):
  File "/opt/airflow/plugins/Postgres2File.py", line 111, in execute
    self._execute(src_hook, context)
  File "/opt/airflow/plugins/Postgres2File.py", line 71, in _execute
    cursor.execute(self.sql)
psycopg2.errors.UndefinedColumn: column "nachn" does not exist
LINE 1: select PERNR, NACHN, VORNA, MIDNM, ORGEH, PLANS, PLTXT, CHPE...
                      ^


During handling of the above exception, another exception occurred:

Traceback (most recent call last):
  File "/home/airflow/.local/lib/python3.7/site-packages/airflow/task/task_runner/standard_task_runner.py", line 85, in _start_by_fork
    args.func(args, dag=self.dag)
  File "/home/airflow/.local/lib/python3.7/site-packages/airflow/cli/cli_parser.py", line 48, in command
    return func(*args, **kwargs)
  File "/home/airflow/.local/lib/python3.7/site-packages/airflow/utils/cli.py", line 92, in wrapper
    return f(*args, **kwargs)
  File "/home/airflow/.local/lib/python3.7/site-packages/airflow/cli/commands/task_command.py", line 298, in task_run
    _run_task_by_selected_method(args, dag, ti)
  File "/home/airflow/.local/lib/python3.7/site-packages/airflow/cli/commands/task_command.py", line 107, in _run_task_by_selected_method
    _run_raw_task(args, ti)
  File "/home/airflow/.local/lib/python3.7/site-packages/airflow/cli/commands/task_command.py", line 184, in _run_raw_task
    error_file=args.error_file,
  File "/home/airflow/.local/lib/python3.7/site-packages/airflow/utils/session.py", line 70, in wrapper
    return func(*args, session=session, **kwargs)
  File "/home/airflow/.local/lib/python3.7/site-packages/airflow/models/taskinstance.py", line 1334, in _run_raw_task
    self._execute_task_with_callbacks(context)
  File "/home/airflow/.local/lib/python3.7/site-packages/airflow/models/taskinstance.py", line 1460, in _execute_task_with_callbacks
    result = self._execute_task(context, self.task)
  File "/home/airflow/.local/lib/python3.7/site-packages/airflow/models/taskinstance.py", line 1516, in _execute_task
    result = execute_callable(context=context)
  File "/opt/airflow/plugins/Postgres2File.py", line 115, in execute
    raise exc
NameError: name 'exc' is not defined
[2022-04-21 21:22:32,352] {local_task_job.py:154} INFO - Task exited with return code 1
[2022-04-21 21:22:32,392] {base.py:79} INFO - Using connection to: id: postgres_default. Host: postgres, Port: 5432, Schema: ***, Login: ***, Password: ***, extra: {}
[2022-04-21 21:22:32,396] {dbapi.py:225} INFO - Running statement: update list_flow_log
                set t_end=NOW(), status=3, code_error=3, comment = '*Task*: transfer_cso_pers'
                where id = 80;, parameters: None
[2022-04-21 21:22:32,397] {dbapi.py:233} INFO - Rows affected: 1
[2022-04-21 21:22:32,411] {local_task_job.py:264} INFO - 0 downstream tasks scheduled from follow-on schedule check
