[2022-04-21 21:07:40,339] {taskinstance.py:1037} INFO - Dependencies all met for <TaskInstance: cso_2295_ipo_2_cso.py.transfer_cso_org manual__2022-04-21T21:07:32.724793+00:00 [queued]>
[2022-04-21 21:07:40,349] {taskinstance.py:1037} INFO - Dependencies all met for <TaskInstance: cso_2295_ipo_2_cso.py.transfer_cso_org manual__2022-04-21T21:07:32.724793+00:00 [queued]>
[2022-04-21 21:07:40,349] {taskinstance.py:1243} INFO - 
--------------------------------------------------------------------------------
[2022-04-21 21:07:40,349] {taskinstance.py:1244} INFO - Starting attempt 1 of 1
[2022-04-21 21:07:40,349] {taskinstance.py:1245} INFO - 
--------------------------------------------------------------------------------
[2022-04-21 21:07:40,361] {taskinstance.py:1264} INFO - Executing <Task(Postgres2File): transfer_cso_org> on 2022-04-21 21:07:32.724793+00:00
[2022-04-21 21:07:40,367] {standard_task_runner.py:52} INFO - Started process 34240 to run task
[2022-04-21 21:07:40,371] {standard_task_runner.py:76} INFO - Running: ['***', 'tasks', 'run', 'cso_2295_ipo_2_cso.py', 'transfer_cso_org', 'manual__2022-04-21T21:07:32.724793+00:00', '--job-id', '854', '--raw', '--subdir', 'DAGS_FOLDER/cso_2295/cso_2295_ipo_2_cso.py', '--cfg-path', '/tmp/tmpiaj3xuv1', '--error-file', '/tmp/tmpcl0opu32']
[2022-04-21 21:07:40,372] {standard_task_runner.py:77} INFO - Job 854: Subtask transfer_cso_org
[2022-04-21 21:07:40,419] {logging_mixin.py:109} INFO - Running <TaskInstance: cso_2295_ipo_2_cso.py.transfer_cso_org manual__2022-04-21T21:07:32.724793+00:00 [running]> on host 22e04adb6bfa
[2022-04-21 21:07:40,452] {taskinstance.py:1431} INFO - Exporting the following env vars:
AIRFLOW_CTX_DAG_OWNER=***
AIRFLOW_CTX_DAG_ID=cso_2295_ipo_2_cso.py
AIRFLOW_CTX_TASK_ID=transfer_cso_org
AIRFLOW_CTX_EXECUTION_DATE=2022-04-21T21:07:32.724793+00:00
AIRFLOW_CTX_DAG_RUN_ID=manual__2022-04-21T21:07:32.724793+00:00
[2022-04-21 21:07:40,462] {base.py:79} INFO - Using connection to: id: postgres_default. Host: postgres, Port: 5432, Schema: ***, Login: ***, Password: ***, extra: {}
[2022-04-21 21:07:40,480] {taskinstance.py:1718} ERROR - Task failed with exception
Traceback (most recent call last):
  File "/opt/airflow/plugins/Postgres2File.py", line 111, in execute
    self._execute(src_hook, context)
  File "/opt/airflow/plugins/Postgres2File.py", line 71, in _execute
    cursor.execute(self.sql)
psycopg2.errors.UndefinedColumn: column "sname" does not exist
LINE 1: select WERKS, BTRTL, ORGEH, LNAME, SNAME, ABBRV, OPRNT, CHPE...
                                           ^
HINT:  Perhaps you meant to reference the column "test_table.lname".


During handling of the above exception, another exception occurred:

Traceback (most recent call last):
  File "/home/airflow/.local/lib/python3.7/site-packages/airflow/models/taskinstance.py", line 1334, in _run_raw_task
    self._execute_task_with_callbacks(context)
  File "/home/airflow/.local/lib/python3.7/site-packages/airflow/models/taskinstance.py", line 1460, in _execute_task_with_callbacks
    result = self._execute_task(context, self.task)
  File "/home/airflow/.local/lib/python3.7/site-packages/airflow/models/taskinstance.py", line 1516, in _execute_task
    result = execute_callable(context=context)
  File "/opt/airflow/plugins/Postgres2File.py", line 115, in execute
    raise exc
NameError: name 'exc' is not defined
[2022-04-21 21:07:40,493] {taskinstance.py:1282} INFO - Marking task as FAILED. dag_id=cso_2295_ipo_2_cso.py, task_id=transfer_cso_org, execution_date=20220421T210732, start_date=20220421T210740, end_date=20220421T210740
[2022-04-21 21:07:40,502] {standard_task_runner.py:92} ERROR - Failed to execute job 854 for task transfer_cso_org
Traceback (most recent call last):
  File "/opt/airflow/plugins/Postgres2File.py", line 111, in execute
    self._execute(src_hook, context)
  File "/opt/airflow/plugins/Postgres2File.py", line 71, in _execute
    cursor.execute(self.sql)
psycopg2.errors.UndefinedColumn: column "sname" does not exist
LINE 1: select WERKS, BTRTL, ORGEH, LNAME, SNAME, ABBRV, OPRNT, CHPE...
                                           ^
HINT:  Perhaps you meant to reference the column "test_table.lname".


During handling of the above exception, another exception occurred:

Traceback (most recent call last):
  File "/home/airflow/.local/lib/python3.7/site-packages/airflow/task/task_runner/standard_task_runner.py", line 85, in _start_by_fork
    args.func(args, dag=self.dag)
  File "/home/airflow/.local/lib/python3.7/site-packages/airflow/cli/cli_parser.py", line 48, in command
    return func(*args, **kwargs)
  File "/home/airflow/.local/lib/python3.7/site-packages/airflow/utils/cli.py", line 92, in wrapper
    return f(*args, **kwargs)
  File "/home/airflow/.local/lib/python3.7/site-packages/airflow/cli/commands/task_command.py", line 298, in task_run
    _run_task_by_selected_method(args, dag, ti)
  File "/home/airflow/.local/lib/python3.7/site-packages/airflow/cli/commands/task_command.py", line 107, in _run_task_by_selected_method
    _run_raw_task(args, ti)
  File "/home/airflow/.local/lib/python3.7/site-packages/airflow/cli/commands/task_command.py", line 184, in _run_raw_task
    error_file=args.error_file,
  File "/home/airflow/.local/lib/python3.7/site-packages/airflow/utils/session.py", line 70, in wrapper
    return func(*args, session=session, **kwargs)
  File "/home/airflow/.local/lib/python3.7/site-packages/airflow/models/taskinstance.py", line 1334, in _run_raw_task
    self._execute_task_with_callbacks(context)
  File "/home/airflow/.local/lib/python3.7/site-packages/airflow/models/taskinstance.py", line 1460, in _execute_task_with_callbacks
    result = self._execute_task(context, self.task)
  File "/home/airflow/.local/lib/python3.7/site-packages/airflow/models/taskinstance.py", line 1516, in _execute_task
    result = execute_callable(context=context)
  File "/opt/airflow/plugins/Postgres2File.py", line 115, in execute
    raise exc
NameError: name 'exc' is not defined
[2022-04-21 21:07:40,547] {local_task_job.py:154} INFO - Task exited with return code 1
[2022-04-21 21:07:40,573] {base.py:79} INFO - Using connection to: id: postgres_default. Host: postgres, Port: 5432, Schema: ***, Login: ***, Password: ***, extra: {}
[2022-04-21 21:07:40,576] {dbapi.py:225} INFO - Running statement: update list_flow_log
                set t_end=NOW(), status=3, code_error=3, comment = '*Task*: transfer_cso_org'
                where id = 71;, parameters: None
[2022-04-21 21:07:40,576] {dbapi.py:233} INFO - Rows affected: 1
[2022-04-21 21:07:40,595] {local_task_job.py:264} INFO - 0 downstream tasks scheduled from follow-on schedule check
