[2022-04-13 13:56:56,860] {taskinstance.py:1037} INFO - Dependencies all met for <TaskInstance: hook_dag.transfer_xml manual__2022-04-13T13:55:52.001868+00:00 [queued]>
[2022-04-13 13:56:56,871] {taskinstance.py:1037} INFO - Dependencies all met for <TaskInstance: hook_dag.transfer_xml manual__2022-04-13T13:55:52.001868+00:00 [queued]>
[2022-04-13 13:56:56,871] {taskinstance.py:1243} INFO - 
--------------------------------------------------------------------------------
[2022-04-13 13:56:56,871] {taskinstance.py:1244} INFO - Starting attempt 2 of 2
[2022-04-13 13:56:56,872] {taskinstance.py:1245} INFO - 
--------------------------------------------------------------------------------
[2022-04-13 13:56:56,880] {taskinstance.py:1264} INFO - Executing <Task(Postgres2File): transfer_xml> on 2022-04-13 13:55:52.001868+00:00
[2022-04-13 13:56:56,889] {standard_task_runner.py:52} INFO - Started process 404 to run task
[2022-04-13 13:56:56,891] {standard_task_runner.py:76} INFO - Running: ['***', 'tasks', 'run', 'hook_dag', 'transfer_xml', 'manual__2022-04-13T13:55:52.001868+00:00', '--job-id', '119', '--raw', '--subdir', 'DAGS_FOLDER/hook_dag.py', '--cfg-path', '/tmp/tmpfvc8_nav', '--error-file', '/tmp/tmpduove9qx']
[2022-04-13 13:56:56,892] {standard_task_runner.py:77} INFO - Job 119: Subtask transfer_xml
[2022-04-13 13:56:56,969] {logging_mixin.py:109} INFO - Running <TaskInstance: hook_dag.transfer_xml manual__2022-04-13T13:55:52.001868+00:00 [running]> on host 9f366f55497f
[2022-04-13 13:56:57,057] {taskinstance.py:1431} INFO - Exporting the following env vars:
AIRFLOW_CTX_DAG_OWNER=***
AIRFLOW_CTX_DAG_ID=hook_dag
AIRFLOW_CTX_TASK_ID=transfer_xml
AIRFLOW_CTX_EXECUTION_DATE=2022-04-13T13:55:52.001868+00:00
AIRFLOW_CTX_DAG_RUN_ID=manual__2022-04-13T13:55:52.001868+00:00
[2022-04-13 13:56:57,075] {base.py:79} INFO - Using connection to: id: postgres_default. Host: postgres, Port: 5432, Schema: ***, Login: ***, Password: ***, extra: {}
[2022-04-13 13:56:57,087] {taskinstance.py:1718} ERROR - Task failed with exception
Traceback (most recent call last):
  File "/opt/airflow/plugins/Postgres2File.py", line 109, in execute
    self._execute(src_hook, context)
  File "/opt/airflow/plugins/Postgres2File.py", line 75, in _execute
    tree = ET.parse(self.parameters, ET.XMLParser(remove_blank_text=True))
  File "src/lxml/etree.pyx", line 3536, in lxml.etree.parse
  File "src/lxml/parser.pxi", line 1876, in lxml.etree._parseDocument
  File "src/lxml/parser.pxi", line 1902, in lxml.etree._parseDocumentFromURL
  File "src/lxml/parser.pxi", line 1805, in lxml.etree._parseDocFromFile
  File "src/lxml/parser.pxi", line 1177, in lxml.etree._BaseParser._parseDocFromFile
  File "src/lxml/parser.pxi", line 615, in lxml.etree._ParserContext._handleParseResultDoc
  File "src/lxml/parser.pxi", line 725, in lxml.etree._handleParseResult
  File "src/lxml/parser.pxi", line 652, in lxml.etree._raiseParseError
OSError: Error reading file './template/orgunit_new.xml': failed to load external entity "./template/orgunit_new.xml"

During handling of the above exception, another exception occurred:

Traceback (most recent call last):
  File "/home/airflow/.local/lib/python3.7/site-packages/airflow/models/taskinstance.py", line 1334, in _run_raw_task
    self._execute_task_with_callbacks(context)
  File "/home/airflow/.local/lib/python3.7/site-packages/airflow/models/taskinstance.py", line 1460, in _execute_task_with_callbacks
    result = self._execute_task(context, self.task)
  File "/home/airflow/.local/lib/python3.7/site-packages/airflow/models/taskinstance.py", line 1516, in _execute_task
    result = execute_callable(context=context)
  File "/opt/airflow/plugins/Postgres2File.py", line 113, in execute
    raise exc
NameError: name 'exc' is not defined
[2022-04-13 13:56:57,099] {taskinstance.py:1282} INFO - Marking task as FAILED. dag_id=hook_dag, task_id=transfer_xml, execution_date=20220413T135552, start_date=20220413T135656, end_date=20220413T135657
[2022-04-13 13:56:57,113] {standard_task_runner.py:92} ERROR - Failed to execute job 119 for task transfer_xml
Traceback (most recent call last):
  File "/opt/airflow/plugins/Postgres2File.py", line 109, in execute
    self._execute(src_hook, context)
  File "/opt/airflow/plugins/Postgres2File.py", line 75, in _execute
    tree = ET.parse(self.parameters, ET.XMLParser(remove_blank_text=True))
  File "src/lxml/etree.pyx", line 3536, in lxml.etree.parse
  File "src/lxml/parser.pxi", line 1876, in lxml.etree._parseDocument
  File "src/lxml/parser.pxi", line 1902, in lxml.etree._parseDocumentFromURL
  File "src/lxml/parser.pxi", line 1805, in lxml.etree._parseDocFromFile
  File "src/lxml/parser.pxi", line 1177, in lxml.etree._BaseParser._parseDocFromFile
  File "src/lxml/parser.pxi", line 615, in lxml.etree._ParserContext._handleParseResultDoc
  File "src/lxml/parser.pxi", line 725, in lxml.etree._handleParseResult
  File "src/lxml/parser.pxi", line 652, in lxml.etree._raiseParseError
OSError: Error reading file './template/orgunit_new.xml': failed to load external entity "./template/orgunit_new.xml"

During handling of the above exception, another exception occurred:

Traceback (most recent call last):
  File "/home/airflow/.local/lib/python3.7/site-packages/airflow/task/task_runner/standard_task_runner.py", line 85, in _start_by_fork
    args.func(args, dag=self.dag)
  File "/home/airflow/.local/lib/python3.7/site-packages/airflow/cli/cli_parser.py", line 48, in command
    return func(*args, **kwargs)
  File "/home/airflow/.local/lib/python3.7/site-packages/airflow/utils/cli.py", line 92, in wrapper
    return f(*args, **kwargs)
  File "/home/airflow/.local/lib/python3.7/site-packages/airflow/cli/commands/task_command.py", line 298, in task_run
    _run_task_by_selected_method(args, dag, ti)
  File "/home/airflow/.local/lib/python3.7/site-packages/airflow/cli/commands/task_command.py", line 107, in _run_task_by_selected_method
    _run_raw_task(args, ti)
  File "/home/airflow/.local/lib/python3.7/site-packages/airflow/cli/commands/task_command.py", line 184, in _run_raw_task
    error_file=args.error_file,
  File "/home/airflow/.local/lib/python3.7/site-packages/airflow/utils/session.py", line 70, in wrapper
    return func(*args, session=session, **kwargs)
  File "/home/airflow/.local/lib/python3.7/site-packages/airflow/models/taskinstance.py", line 1334, in _run_raw_task
    self._execute_task_with_callbacks(context)
  File "/home/airflow/.local/lib/python3.7/site-packages/airflow/models/taskinstance.py", line 1460, in _execute_task_with_callbacks
    result = self._execute_task(context, self.task)
  File "/home/airflow/.local/lib/python3.7/site-packages/airflow/models/taskinstance.py", line 1516, in _execute_task
    result = execute_callable(context=context)
  File "/opt/airflow/plugins/Postgres2File.py", line 113, in execute
    raise exc
NameError: name 'exc' is not defined
[2022-04-13 13:56:57,150] {local_task_job.py:154} INFO - Task exited with return code 1
[2022-04-13 13:56:57,215] {local_task_job.py:264} INFO - 0 downstream tasks scheduled from follow-on schedule check
